Workbook
Name Comprar: [1]Param!#REF!
Name início_da_tarefa: [2]CronogramaDeProjeto!$E1
Name Início_do_projeto: '[3]Gráfico de Gantt'!$G$5
Name Início_do_projeto: '[3]Gráfico de Gantt'!$G$5
Name Início_do_projeto: '[4]Gráfico de Gantt'!$G$5
Name Início_do_projeto: '[4]Gráfico de Gantt'!$G$5
Name Início_do_projeto: '[3]Gráfico de Gantt'!$G$5
Name Início_do_projeto: '[4]Gráfico de Gantt'!$G$5
Name Início_do_projeto: '[3]Gráfico de Gantt'!$G$5
Name Início_do_projeto: '[4]Gráfico de Gantt'!$G$5
Name Início_do_projeto: '[5]Gráfico de Gantt'!$G$5
Name Início_do_projeto: '[3]Gráfico de Gantt'!$G$5
Name Início_do_projeto: 'Gráfico de Gantt'!$G$5
Name Periodicidade: [6]Param!$AB$5:$AB$9
Name progresso_da_tarefa: [2]CronogramaDeProjeto!$D1
Name Semana_de_exibição: '[3]Gráfico de Gantt'!$G$6
Name Semana_de_exibição: '[3]Gráfico de Gantt'!$G$6
Name Semana_de_exibição: '[4]Gráfico de Gantt'!$G$6
Name Semana_de_exibição: '[4]Gráfico de Gantt'!$G$6
Name Semana_de_exibição: '[3]Gráfico de Gantt'!$G$6
Name Semana_de_exibição: '[4]Gráfico de Gantt'!$G$6
Name Semana_de_exibição: '[3]Gráfico de Gantt'!$G$6
Name Semana_de_exibição: '[4]Gráfico de Gantt'!$G$6
Name Semana_de_exibição: '[5]Gráfico de Gantt'!$G$6
Name Semana_de_exibição: '[3]Gráfico de Gantt'!$G$6
Name Semana_de_exibição: 'Gráfico de Gantt'!$G$6
Name Status: [1]Param!#REF!
Name término_da_tarefa: [2]CronogramaDeProjeto!$F1
Name VersaoExcel: [6]Param!$D$15:$E$15
Name VersaoSR: [6]Param!$C$24:$C$26

Sheet Project Charter

Sheet WBS-MACRO-ATIVIDADE

Sheet WBS_Detalhado (ordem etapas)
B7: 4.1 Plano de ação detalhado da WBS (com dependência, tempo e recurso) | P7: FAREMOS MAIS PARA FRENTE
B9: Ref | C9: Etapas – Atividades - | D9: Dependência | E9: Data Início | F9: Data Fim | G9: Duração em semanas | H9: Conclusão | I9: Responsável | J9: Recursos | K9: Custos | L9: Obs | O9: Rede de Precedência de Atividades
B10: 1 | C10: Iniciação | D10: — | E10: 45873 | F10: 45880 | P10: Atividades | Q10: Dependência | R10: Duração em semanas
B11: 1.1 | C11: Entendimento das necessidades do cliente | D11: 1 | E11: 45873 | F11: 45874 | G11: 1 | H11: 1ª | I11: GERENTE DE PROJETO | J11: Pessoas | K11: 200 | O11: 1 | P11: Iniciação | Q11: NÃO | R11: 6
B12: 1.2 | C12: Formação da equipe de design e desenvolvimento | D12: 1.1 | E12: 45875 | F12: 45876 | G12: 1 | H12: 1ª | I12: GERENTE DE PROJETO | J12: Pessoas | K12: 150 | O12: 2 | P12: Planejamento | Q12: Iniciação | R12: 11
B13: 1.3 | C13: Identificação de funcionalidades e recursos | D13: 1.2 | E13: 45877 | F13: 45880 | G13: 1 | H13: 1ª | I13: GERENTE DE PROJETO | J13: Pessoas | K13: 220 | O13: 3 | P13: Design e Prototipagem | Q13: Iniciação | R13: 8
B14: 2 | C14: Planejamento | D14: 1.3 | E14: 45881 | F14: 45891 | G14: 1 | H14: 2ª | K14: =SUM(K11:K13) -> 570 | O14: 4 | P14: Desenvolvimento | Q14: Planejamento/Design e Prototipagem | R14: 11
B15: 2.1 | C15: Análise de mercado (foodtechs e concorrentes) | D15: 1.3 | E15: 45881 | F15: 45882 | G15: 2 | H15: 2ª | I15: GERENTE DE PROJETO | J15: Pessoas | K15: 180 | O15: 5 | P15: Integração com sistemas de monitoramento de saúde | Q15: Desenvolvimento | R15: 5
B16: 2.2 | C16: Definir os requisitos detalhados do sistema | D16: 2.1 | E16: 45883 | F16: 45890 | G16: 1 | H16: 2ª | I16: GERENTE DE PROJETO | J16: Pessoas | K16: 250 | O16: 6 | P16: Testes | Q16: Integração com sistemas de monitoramento de saúde | R16: 3
B17: 2.2.1 | C17: Definição de stakeholders | D17: 2.2 | E17: 45883 | F17: 45884 | G17: 2 | H17: 2ª | I17: GERENTE DE PROJETO | J17: Pessoas | K17: 150 | O17: 7 | P17: Lançamento (Stakeholders internos) | Q17: Testes | R17: 6
B18: 2.2.2 | C18: Planos de pesquisa de público-alvo | D18: 2.2.1 | E18: 45887 | F18: 45888 | G18: 1 | H18: 1ª | I18: GERENTE DE PROJETO | J18: Pessoas | K18: 150 | O18: 8 | P18: Pós-lançamento (Stakeholders internos) | Q18: Lançamento (Stakeholders internos) | R18: 6
B19: 2.2.3 | C19: Pesquisa por ferramentas | D19: 2.2.2 | E19: 45889 | F19: 45889 | G19: 1 | H19: 1ª | I19: GERENTE DE PROJETO | J19: Pessoas | K19: 120 | O19: 9 | P19: Marketing e Divulgação para o Mercado | Q19: Pós-lançamento (Stakeholders internos) | R19: 6
B20: 2.2.4 | C20: Integração com sistemas de banco de dados | D20: 2.2.3 | E20: 45890 | F20: 45890 | G20: 1 | H20: 1ª | I20: GERENTE DE PROJETO | J20: Pessoas | K20: 130 | O20: 10 | P20: Avaliação e Aperfeiçoamento | Q20: Marketing e Divulgação | R20: 6
B21: 2.2.5 | C21: Criação de cronograma e metas | D21: 2.2.4 | E21: 45891 | F21: 45891 | G21: 1 | H21: 1ª | I21: GERENTE DE PROJETO | J21: Pessoas | K21: 120 | O21: 11 | P21: Expansão | Q21: Avaliação e Aperfeiçoamento | R21: 6
B22: 3 | C22: Design e Prototipagem | D22: 2.2.5 | E22: 45894 | F22: 45905 | G22: 1 | H22: 1ª | K22: =SUM(K15:K21) -> 1100
B23: 3.1 | C23: Design UI | D23: 2.2.5 | E23: 45894 | F23: 45895 | G23: 2 | H23: 2ª | I23: DESIGN | J23: Pessoas | K23: 220
B24: 3.2 | C24: Design UX | D24: 3.1 | E24: 45896 | F24: 45897 | G24: 1 | H24: 1ª | I24: DESIGN | J24: Pessoas | K24: 220
B25: 3.3 | C25: Navegação e funcionalidades | D25: 3.2 | E25: 45898 | F25: 45898 | G25: 1 | H25: 1ª | I25: DESIGN | J25: Pessoas | K25: 180
B26: 3.4 | C26: Protótipos interativos | D26: 3.3 | E26: 45901 | F26: 45902 | G26: 1 | H26: 1ª | I26: DESIGN | J26: Pessoas | K26: 220
B27: 3.5 | C27: Interface limpa e intuitiva | D27: 3.4 | E27: 45903 | F27: 45903 | G27: 1 | H27: 1ª | I27: DESIGN | J27: Pessoas | K27: 180
B28: 3.6 | C28: Teste de UI / UX | D28: 3.5 | E28: 45904 | F28: 45905 | G28: 1 | H28: 1ª | I28: DESIGN | J28: Pessoas | K28: 220
B29: 4 | C29: Desenvolvimento | D29: 3.6 | E29: 45908 | F29: 45926 | G29: 1 | H29: 1ª | K29: =SUM(K23:K28) -> 1240
B30: 4.1 | C30: Definir a estrutura do sistema | D30: 3.6 | E30: 45908 | F30: 45910 | G30: 3 | H30: 3ª | I30: DESENVOLVIMENTO | J30: Pessoas | K30: 250
B31: 4.2 | C31: Desenvolver módulos principais | D31: 4.1 | E31: 45911 | F31: 45926 | G31: 2 | H31: 2ª | I31: DESENVOLVIMENTO | J31: Pessoas | K31: 260
B32: 4.2.1 | C32: Código front-end | D32: 4.2 | E32: 45911 | F32: 45915 | G32: 3 | H32: 3ª | I32: DESENVOLVIMENTO | J32: Pessoas | K32: 300
B33: 4.2.2 | C33: Código back-end | D33: 4.2.1 | E33: 45916 | F33: 45918 | G33: 2 | H33: 1ª | I33: DESENVOLVIMENTO | J33: Pessoas | K33: 260
B34: 4.2.3 | C34: Gerador de planos de adaptação | D34: 4.2.2 | E34: 45919 | F34: 45923 | G34: 2 | H34: 2ª | I34: DESENVOLVIMENTO | J34: Pessoas | K34: 240
B35: 4.2.4 | C35: Módulo de identificação e captação de cliente | D35: 4.2.3 | E35: 45924 | F35: 45926 | G35: 2 | H35: 2ª | I35: DESENVOLVIMENTO | J35: Pessoas | K35: 240
B36: 5 | C36: Integração com APIs | D36: 4.2.4 | E36: 45929 | F36: 45936 | G36: 1 | H36: 1ª | I36: DESENVOLVIMENTO | J36: Pessoas | K36: 240
B37: 5.1 | C37: Integração com sistemas de monitoramento de saúde | D37: 5 | E37: 45929 | F37: 45930 | G37: 2 | H37: 2ª | K37: =SUM(K23:K28) -> 1240
B38: 5.2 | C38: Integração com diversos sistemas | D38: 5.1 | E38: 45931 | F38: 45932 | G38: 1 | H38: 2ª | I38: SEGURANÇA | J38: Pessoas | K38: 180
B39: 5.3 | C39: Garantia de segurança e privacidade | D39: 5.2 | E39: 45933 | F39: 45936 | G39: 1 | H39: 2ª | I39: SEGURANÇA | J39: Pessoas | K39: 200
B40: 6 | C40: Integração e sincronização de dados | D40: 5.3 | E40: 45937 | F40: 45943 | G40: 1 | H40: 2ª | I40: SEGURANÇA | J40: Pessoas | K40: 500
B41: 6.1 | C41: Testes | D41: 5.3 | E41: 45937 | F41: 45938 | G41: 1 | H41: 1ª | K41: =SUM(K38:K40) -> 880
B42: 6.1.2 | C42: Testes de qualidade e desempenho | D42: 6.1 | E42: 45939 | F42: 45939 | G42: 1 | H42: 1ª | I42: QUALIDADE | J42: Pessoas | K42: 200
B43: 6.1.3 | C43: Testes de usabilidade | D43: 6.1.2 | E43: 45940 | F43: 45943 | G43: 1 | H43: 1ª | I43: QUALIDADE | J43: Pessoas | K43: 260
B44: 7 | C44: Identificação e correção de bugs | D44: 6.1.3 | E44: 45944 | F44: 45950 | G44: 1 | H44: 1ª | I44: QUALIDADE | J44: Pessoas | K44: 400
B45: 7.1.1 | C45: Lançamento (Stakeholders internos) | D45: 6.1.3 | E45: 45944 | F45: 45945 | G45: 1 | H45: 1ª | K45: =SUM(K42:K44) -> 860
B46: 7.1.2 | C46: Criar material de marketing para o cliente | D46: 7.1.1 | E46: 45946 | F46: 45946 | G46: 1 | H46: 2ª | I46: REDES | J46: Pessoas | K46: 200
B47: 7.1.3 | C47: Criar materiais de marketing | D47: 7.1.2 | E47: 45947 | F47: 45950 | G47: 1 | H47: 2ª | I47: COMERCIAL | J47: Pessoas | K47: 240
...

Sheet WBS_Detalhado (ordem depend)
B6: 4.2 Plano de ação detalhado da WBS (com dependência, tempo e recurso)
B8: Ref | C8: Etapas – Atividades - | D8: Dependência | E8: Duração em semanas | F8: Conclusão | G8: Responsável | H8: Recursos | I8: Obs
B9: 1.1 | C9: Entendimento das necessidades do cliente | D9: 1 | E9: 1 | F9: 1ª | G9: GERENTE DE PROJETO | H9: Pessoas | I9: -
B10: 1.2 | C10: Formação da equipe de design e desenvolvimento | D10: 1.1 | E10: 1 | F10: 2ª | G10: GERENTE DE PROJETO | H10: Pessoas | I10: -
B11: 1.3 | C11: Identificação de funcionalidades e recursos | D11: 1.2 | E11: 1 | F11: 2ª | G11: GERENTE DE PROJETO | H11: Pessoas
B12: 2.1 | C12: Análise de mercado (concorrentes e tendências foodtech) | D12: 1.3 | E12: 2 | F12: 2ª | G12: GERENTE DE PROJETO | H12: Pessoas
B13: 2.2 | C13: Definição dos requisitos detalhados do sistema | D13: 2.1 | E13: 1 | F13: 2ª | G13: GERENTE DE PROJETO | H13: Pessoas
B14: 2.2.1 | C14: Identificação dos stakeholders | D14: 2.2 | E14: 2 | F14: 2ª | G14: GERENTE DE PROJETO | H14: Pessoas | I14: -
B15: 2.2.2 | C15: Pesquisa de público-alvo | D15: 2.2.1 | E15: 1 | F15: 2ª | G15: GERENTE DE PROJETO | H15: Pessoas | I15: -
B16: 2.2.3 | C16: Levantamento de ferramentas tecnológicas | D16: 2.2.2 | E16: 1 | F16: 1ª | G16: GERENTE DE PROJETO | H16: Pessoas | I16: -
B17: 2.2.4 | C17: Planejamento de integração com banco de dados | D17: 2.2.3 | E17: 1 | F17: 1ª | G17: GERENTE DE PROJETO | H17: Pessoas | I17: -
B18: 2.2.5 | C18: Definição do cronograma e metas | D18: 2.2.4 | E18: 1 | F18: 2ª | G18: GERENTE DE PROJETO | H18: Pessoas | I18: -
B19: 3.1 | C19: Design da interface (UI) | D19: 2.2.5 | E19: 2 | F19: 1ª | G19: DESIGN | H19: Pessoas | I19: -
B20: 3.2 | C20: Estrutura de experiência do usuário (UX) | D20: 3.1 | E20: 1 | F20: 1ª | G20: DESIGN | H20: Pessoas | I20: -
B21: 3.3 | C21: Definição da navegação e funcionalidades | D21: 3.2 | E21: 1 | F21: 1ª | G21: DESIGN | H21: Pessoas | I21: -
B22: 3.4 | C22: Criação de protótipos interativos | D22: 3.3 | E22: 1 | F22: 1ª | G22: DESIGN | H22: Pessoas | I22: -
B23: 3.5 | C23: Ajuste para interface limpa e intuitiva | D23: 3.4 | E23: 1 | F23: 1ª | G23: DESIGN | H23: Pessoas | I23: -
B24: 3.6 | C24: Testes de usabilidade da UI/UX | D24: 3.5 | E24: 1 | F24: 2ª | G24: DESIGN | H24: Pessoas | I24: -
B25: 4.1 | C25: Definição da arquitetura do sistema | D25: 3.6 | E25: 3 | F25: 2ª | G25: DESENVOLVIMENTO | H25: Pessoas | I25: -
... B30: 4.2.4 | C30: Implementação do módulo de identificação e captação de clientes | D30: 4.2.3 | E30: 2 | F30: 2ª | G30: DESENVOLVIMENTO | H30: Pessoas | I30: -
B31: 5 | C31: Integração com APIs externas | D31: 4.2.4 | E31: 1 | F31: 1ª | G31: DESENVOLVIMENTO | H31: Pessoas | I31: -
B32: 5.2 | C32: Integração com sistemas internos/externos | D32: 5.1 | E32: 1 | F32: 2ª | G32: SEGURANÇA | H32: Pessoas | I32: -
B33: 5.3 | C33: Garantia de segurança e privacidade dos dados | D33: 5.2 | E33: 1 | F33: 2ª | G33: SEGURANÇA | H33: Pessoas | I33: -
B34: 6 | C34: Sincronização de dados em tempo real | D34: 5.3 | E34: 1 | F34: 2ª | G34: SEGURANÇA | H34: Pessoas | I34: -
B35: 6.1.2 | C35: Testes de qualidade e desempenho | D35: 6.1 | E35: 1 | F35: 1ª | G35: QUALIDADE | H35: Pessoas | I35: -
B36: 6.1.3 | C36: Testes de usabilidade | D36: 6.1.2 | E36: 1 | F36: 1ª | G36: QUALIDADE | H36: Pessoas | I36: -
B37: 7 | C37: Identificar e corrigir bugs e problemas de interface | D37: 6.1.3 | E37: 1 | F37: 1ª | G37: QUALIDADE | H37: Pessoas | I37: -
B38: 7.1.2 | C38: Identificação e correção de bugs | D38: 7.1.1 | E38: 1 | F38: 1ª | G38: REDES | H38: Pessoas | I38: -
B39: 7.1.3 | C39: Criação de material de marketing para clientes | D39: 7.1.2 | E39: 1 | F39: 2ª | G39: COMERCIAL | H39: Pessoas | I39: -
B40: 8 | C40: Produção de materiais promocionais internos/externos | D40: 7.1.3 | E40: 1 | F40: 2ª | G40: COMERCIAL | H40: Pessoas | I40: -
B41: 8.1.2 | C41: Preparação da infraestrutura de publicação | D41: 8.1.1 | E41: 1 | F41: 2ª | G41: EQUIPE TÉCNICA | H41: Pessoas | I41: -
B42: 8.1.3 | C42: Avaliação nas lojas/plataformas de aplicativos | D42: 8.1.2 | E42: 1 | F42: 2ª | G42: EQUIPE TÉCNICA | H42: Pessoas | I42: -
B43: 9 | C43: Monitoramento de métricas e coleta de feedback | D43: 8.1.3 | E43: 1 | F43: 2ª | G43: EQUIPE TÉCNICA | H43: Pessoas | I43: -
B44: 9.1.2 | C44: Atualizações e melhorias contínuas | D44: 9.1.1 | E44: 1 | F44: 2ª | G44: EQUIPE TÉCNICA | H44: Pessoas | I44: -
B45: 9.1.3 | C45: Suporte e resolução de dúvidas | D45: 9.1.2 | E45: 1 | F45: 2ª | G45: EQUIPE TÉCNICA | H45: Pessoas | I45: -
B46: 10 | C46: Definição de estratégias de marketing | D46: 9.1.3 | E46: 1 | F46: 2ª | G46: EQUIPE TÉCNICA | H46: Pessoas | I46: -
B47: 10.1.2 | C47: Parcerias e colaboração com sistemas de reviews | D47: 10.1.1 | E47: 1 | F47: 2ª | G47: DESEMPENHO | H47: Pessoas | I47: -
B48: 10.1.3 | C48: Campanhas em mídias sociais e anúncios online | D48: 10.1.2 | E48: 1 | F48: 2ª | G48: COMERCIAL | H48: Pessoas | I48: -
B49: 11 | C49: Análise de desempenho do dashboard | D49: 10.1.3 | E49: 1 | F49: 2ª | G49: COMERCIAL | H49: Pessoas | I49: -
B50: 11.1.2 | C50: Coleta de feedback e implementação de melhorias | D50: 11.1.1 | E50: 1 | F50: 2ª | G50: EQUIPE TÉCNICA | H50: Pessoas | I50: -
...

Sheet WBS- PLANILHA
A1: Análise de Stakeholders
A2: Projeto | B2: InovaTech
A3: Gerente do Projeto | B3: Adeilson, Bruna, Enzo, Daniela e Rafaela
A8: Entregas do Projeto | B8: A definir | C8: Atulizado Em | D8: 45901
A10: SAM | I10: SRM
A11: Stakeholder | B11: Objetivos | C11: Metas | D11: Motivações e Interesses | E11: Poder e influência | F11: Importância e Impacto | G11: Papéis & Responsabilidades | H11: Sintonia "fina" | I11: Área de Interesse | J11: Nível de Detalhe | K11: Formato | L11: Frequência | M11: Mecanismo de Entrega
A12: Cliente (Usuários Finais) | B12: Fornecer dados que comprovem a eficiência da análise de dados da Cannoli | C12: Capitar dados dos clientes e fazer uma análise eficiente e detalhada. | D12: Ser eficiente na análise de dado e no retorno visual dos dados. | E12: Influenciam o sucesso do trabalho de divulgação da Cannoli por meio de dados e feedback. | F12: Essencial para a aceitação e popularidade do sistema. | G12: Usar o sistema, fornecer feedback para a Cannoli, compartilhar dados. | H12: Manter os clientes satisfeitos, garantir que o aplicativo atenda às suas necessidades. | I12: Análise de dados | J12: Relatórios concisos e informativos, que destaquem eficiência da Cannoli para os clientes dela | K12: Coletar dados e analisa-los através de sistema digital. | L12: Diariamente. Ou conforme desejo do cliente. | M12: Relatórios entregues por sistema digital.
A13: Product Owner | B13: Garantir que o dashboard atenda às necessidades de negócio e esteja alinhado à visão estratégica do produto Cannoli. | C13: Priorizar backlog, validar requisitos, acompanhar desenvolvimento e assegurar entrega de valor contínuo. | D13: Garantir sucesso do produto no mercado, maximizar o ROI e manter o alinhamento entre áreas técnicas e de negócio. | E13: Alto (define prioridades, backlog e critérios de aceitação). | F13: Essencial para direcionar o time de desenvolvimento e garantir entregas de valor. | G13: Gerenciar backlog, definir prioridades, validar entregas, atuar como elo entre stakeholders e time técnico. | H13: Manter comunicação constante com desenvolvedores, marketing e alta gestão para alinhar expectativas. | I13: Estratégia do produto, roadmap, backlog, KPIs estratégicos. | J13: Alto (detalhes técnicos e de negócio para validação de requisitos). | K13: Relatórios executivos do andamento do backlog e dashboards de progresso. | L13: Semanal (sprints, reviews) e mensal (alinhamento estratégico). | M13: Reuniões rReuniões de sprint review, relatórios digitais e dashboards compartilhados.emotas, relatórios enviados por e-mail.
A14: Desenvolvedores | B14: Entregar um dashboard funcional, seguro e responsivo, com dados consistentes e IA básica. | C14: Concluir o MVP dentro do prazo, garantir qualidade técnica e atender requisitos funcionais/não funcionais. | D14: Aprendizado prático, desenvolvimento de portfólio, sucesso do projeto. | E14: Alto (definem viabilidade técnica e velocidade de entrega). | F14: Muito alto (sem eles não há entrega). | G14: Programar backend/frontend, modelar dados, implementar KPIs/IA, testar e documentar. | H14: Necessário alinhamento constante com Time Comercial e Stakeholders. | I14: Tecnologia e inovação (dev, dados, IA, segurança). | J14: Alto (precisam de requisitos claros e detalhados). | K14: Reuniões técnicas, backlog/Trello/GitHub. | L14: Semanal (sprints) + checkpoints rápidos. | M14: Relatórios de progresso, commits no repositório, versões do sistema.
A15: Time Comercial | B15: Garantir que o dashboard atenda às necessidades dos restaurantes e admins da Cannoli. | C15: Validar KPIs estratégicos, apoiar na definição de métricas e simulações de campanhas. | D15: Sucesso do produto no mercado, aumento de engajamento/fidelização, clareza nos dados. | E15: Médio (influenciam requisitos de negócio, mas não a execução técnica). | F15: Alto (sem alinhamento, risco de desenvolver algo que não gera valor). | G15: Definir requisitos de negócio, validar KPIs, dar feedback contínuo, apresentar aos stakeholders externos. | H15: Precisa estar em contato constante com Desenvolvedores e Administradores Cannoli. | I15: Estratégia, vendas, métricas de engajamento e campanhas. | J15: Médio (querem visão consolidada, não detalhes técnicos). | K15: Relatórios executivos, apresentações visuais do dashboard. | L15: Quinzenal (validação de entregas) + sob demanda em fases críticas. | M15: Demonstrações do dashboard, relatórios resumidos, reuniões de validação.
A16: Marketing | B16: Garantir que o dashboard gere insights úteis para campanhas e estratégias de engajamento. | C16: Apoiar na definição de métricas de retenção, ticket médio, comportamento do cliente e resultados de campanhas. | D16: Aumentar engajamento dos clientes, melhorar ROI das campanhas, ampliar a base de restaurantes parceiros. | E16: Médio (influencia requisitos de relatórios e indicadores, mas depende da equipe técnica para execução) | F16: Alto (as campanhas são decisivas para o sucesso do produto no mercado). | G16: Definir KPIs de marketing, validar relatórios, sugerir novas métricas de análise. | H16: Precisa alinhar com Desenvolvedores e Comercial para que os relatórios reflitam necessidades reais. | I16: Engajamento, campanhas, retenção, funil de clientes. | J16: Médio (querem relatórios claros e acionáveis). | K16: Relatórios visuais, gráficos e dashboards de impacto. | L16: Quinzenal ou mensal (dependendo do ciclo de campanhas). | M16: Relatórios executivos, dashboards interativos, reuniões de alinhamento.
A17: UX (User Experience) | B17: Garantir que a interface do dashboard seja intuitiva, responsiva e agradável de usar. | C17: Validar protótipos, acompanhar usabilidade, propor melhorias na navegação e acessibilidade. | D17: Aumentar satisfação dos usuários, reduzir curva de aprendizado, facilitar adoção do sistema. | E17: Médio (definem padrões de experiência, mas dependem dos devs para aplicar). | F17: Mantêm clientes engajados e reduzem riscos de abandono da plataforma. | G17: Criar protótipos, validar fluxos de navegação, aplicar testes de usabilidade, recomendar ajustes. | H17: Alinhamento próximo com Desenvolvedores e Comercial para equilibrar experiência e requisitos de negócio. | I17: Design, usabilidade, acessibilidade, responsividade. | J17: Alto (precisam entender microinterações e feedbacks de interface). | K17: Wireframes, protótipos, relatórios de testes de usabilidade. | L17: Semanal (durante fases de design e testes). | M17: Protótipos em Figma, relatórios de testes, reuniões de feedback.
A18: Equipe de Suporte ao Cliente | B18: Resolver problemas técnicos reportados pelos usuários e garantir suporte eficiente. | C18: Resolução rápida de problemas e satisfação contínua dos administradores e restaurantes. | D18: Manter os clientes satisfeitos, reduzir falhas no uso do sistema e garantir continuidade operacional. | E18: Podem influenciar diretamente a satisfação e retenção dos usuários finais. | F18: Mantêm os clientes satisfeitos e engajados. | G18: Responder dúvidas, resolver problemas técnicos, registrar feedback e encaminhar melhorias. | H18: Fornecer suporte ágil e eficaz, garantindo confiança no uso do dashboard. | I18: Problemas recorrentes de acesso, falhas técnicas e relatórios de uso da plataforma. | J18: Médio (detalhes sobre falhas, prazos de resolução e satisfação). | K18: Relatórios de incidentes e feedback estruturado. | L18: Mensal ou conforme demanda dos usuários. | M18: Reuniões virtuais e relatórios digitais enviados por e-mail/sistema.
A19: Gerência Executiva/Alta Administração | B19: Alinhar o dashboard com a visão estratégica da empresa, garantindo retorno financeiro e sucesso no mercado. | C19: Crescimento da base de clientes, aumento do ROI e fortalecimento da marca Cannoli. | D19: Sucesso do produto, crescimento financeiro e posicionamento competitivo. | E19: Definem estratégias, disponibilizam recursos e estabelecem prioridades. | F19: Decidem o rumo do produto e o impacto no negócio. | G19: Definir metas estratégicas, validar indicadores-chave, alocar recursos e acompanhar resultados. | H19: Manter alinhamento entre o dashboard e os objetivos estratégicos da empresa. | I19: Indicadores financeiros, métricas de ROI, crescimento da base de restaurantes parceiros. | J19: Alto (relatórios executivos consolidados com indicadores estratégicos). | K19: Relatórios executivos, dashboards de impacto e apresentações em PPT. | L19: Mensal ou trimestral, dependendo do ciclo estratégico. | M19: Reuniões presenciais ou virtuais, com relatórios e dashboards digitais.

Sheet Segunda Entrega -->

Sheet REDE_PERT_CPM-
A1: Ref | B1: Atividade | C1: Dependência | D1: Duração | E1: ES | F1: EF | G1: LS | H1: LF | I1: Folga | J1: Caminho Crítico | K1: Pred1 | L1: Pred2 | M1: Pred3 | N1: Makespan(M2) | O1: MinES_sucessoras
A2: 1 | B2: 1A. Definição dos objetivos do Projeto | D2: 3 | E2: =MAX(IFERROR(VLOOKUP(K2,$A$2:$F$21,6,FALSE),0),IFERROR(VLOOKUP(L2,$A$2:$F$21,6,FALSE),0),IFERROR(VLOOKUP(M2,$A$2:$F$21,6,FALSE),0)) -> 0 | F2: =E2+D2 -> 3 | G2: =H2-D2 -> 0 | H2: =IF(O2=1E+99,$N$2,O2) -> 3 | I2: =G2-E2 -> 0 | J2: =IF(I2=0,"Sim","Não") -> Sim | N2: 3 | O2: =MIN(IF($K$2:$K$21=A2,$E$2:$E$21,1E+99),IF($L$2:$L$21=A2,$E$2:$E$21,1E+99),IF($M$2:$M$21=A2,$E$2:$E$21,1E+99)) -> 1e+99
A3: 2 | B3: 1B. Formação da equipe do projeto | D3: 2 | E3: =MAX(IFERROR(VLOOKUP(K3,$A$2:$F$21,6,FALSE),0),IFERROR(VLOOKUP(L3,$A$2:$F$21,6,FALSE),0),IFERROR(VLOOKUP(M3,$A$2:$F$21,6,FALSE),0)) -> 0 | F3: =E3+D3 -> 2 | G3: =H3-D3 -> 1 | H3: =IF(O3=1E+99,$N$2,O3) -> 3 | I3: =G3-E3 -> 1 | J3: =IF(I3=0,"Sim","Não") -> Não | O3: =MIN(IF($K$2:$K$21=A3,$E$2:$E$21,1E+99),IF($L$2:$L$21=A3,$E$2:$E$21,1E+99),IF($M$2:$M$21=A3,$E$2:$E$21,1E+99)) -> 1e+99
A4: 3 | B4: 1C. Identificação dos stakeholders | C4: 1 | D4: 3 | E4: =MAX(IFERROR(VLOOKUP(K4,$A$2:$F$21,6,FALSE),0),IFERROR(VLOOKUP(L4,$A$2:$F$21,6,FALSE),0),IFERROR(VLOOKUP(M4,$A$2:$F$21,6,FALSE),0)) -> 0 | F4: =E4+D4 -> 3 | G4: =H4-D4 -> 0 | H4: =IF(O4=1E+99,$N$2,O4) -> 3 | I4: =G4-E4 -> 0 | J4: =IF(I4=0,"Sim","Não") -> Sim | K4: 1 | O4: =MIN(IF($K$2:$K$21=A4,$E$2:$E$21,1E+99),IF($L$2:$L$21=A4,$E$2:$E$21,1E+99),IF($M$2:$M$21=A4,$E$2:$E$21,1E+99)) -> 1e+99
A5: 4 | B5: 1D. Reunião de Kick Off | C5: 3 | D5: 1 | E5: =MAX(IFERROR(VLOOKUP(K5,$A$2:$F$21,6,FALSE),0),IFERROR(VLOOKUP(L5,$A$2:$F$21,6,FALSE),0),IFERROR(VLOOKUP(M5,$A$2:$F$21,6,FALSE),0)) -> 0 | F5: =E5+D5 -> 1 | G5: =H5-D5 -> 2 | H5: =IF(O5=1E+99,$N$2,O5) -> 3 | I5: =G5-E5 -> 2 | J5: =IF(I5=0,"Sim","Não") -> Não | K5: 3 | O5: =MIN(IF($K$2:$K$21=A5,$E$2:$E$21,1E+99),IF($L$2:$L$21=A5,$E$2:$E$21,1E+99),IF($M$2:$M$21=A5,$E$2:$E$21,1E+99)) -> 1e+99
A6: 5 | B6: 2A. Levantamento de Requisitos | C6: 2,3 | D6: 3 | E6: =MAX(IFERROR(VLOOKUP(K6,$A$2:$F$21,6,FALSE),0),IFERROR(VLOOKUP(L6,$A$2:$F$21,6,FALSE),0),IFERROR(VLOOKUP(M6,$A$2:$F$21,6,FALSE),0)) -> 0 | F6: =E6+D6 -> 3 | G6: =H6-D6 -> 0 | H6: =IF(O6=1E+99,$N$2,O6) -> 3 | I6: =G6-E6 -> 0 | J6: =IF(I6=0,"Sim","Não") -> Sim | K6: 2 | L6: 3 | O6: =MIN(IF($K$2:$K$21=A6,$E$2:$E$21,1E+99),IF($L$2:$L$21=A6,$E$2:$E$21,1E+99),IF($M$2:$M$21=A6,$E$2:$E$21,1E+99)) -> 1e+99
A7: 6 | B7: 2B. Entrevistas com Cannoli e Restaurantes | C7: 4 | D7: 2 | E7: =MAX(IFERROR(VLOOKUP(K7,$A$2:$F$21,6,FALSE),0),IFERROR(VLOOKUP(L7,$A$2:$F$21,6,FALSE),0),IFERROR(VLOOKUP(M7,$A$2:$F$21,6,FALSE),0)) -> 0 | F7: =E7+D7 -> 2 | G7: =H7-D7 -> 1 | H7: =IF(O7=1E+99,$N$2,O7) -> 3 | I7: =G7-E7 -> 1 | J7: =IF(I7=0,"Sim","Não") -> Não | K7: 4 | O7: =MIN(IF($K$2:$K$21=A7,$E$2:$E$21,1E+99),IF($L$2:$L$21=A7,$E$2:$E$21,1E+99),IF($M$2:$M$21=A7,$E$2:$E$21,1E+99)) -> 1e+99
A8: 7 | B8: 2C. Documentação de Requisitos Funcionais | C8: 5,6 | D8: 3 | E8: =MAX(IFERROR(VLOOKUP(K8,$A$2:$F$21,6,FALSE),0),IFERROR(VLOOKUP(L8,$A$2:$F$21,6,FALSE),0),IFERROR(VLOOKUP(M8,$A$2:$F$21,6,FALSE),0)) -> 0 | F8: =E8+D8 -> 3 | G8: =H8-D8 -> 0 | H8: =IF(O8=1E+99,$N$2,O8) -> 3 | I8: =G8-E8 -> 0 | J8: =IF(I8=0,"Sim","Não") -> Sim | K8: 5 | L8: 6 | O8: =MIN(IF($K$2:$K$21=A8,$E$2:$E$21,1E+99),IF($L$2:$L$21=A8,$E$2:$E$21,1E+99),IF($M$2:$M$21=A8,$E$2:$E$21,1E+99)) -> 1e+99
A9: 8 | B9: 2D. Documentação de Requisitos Não Funcionais | C9: 4,6 | D9: 3 | E9: =MAX(IFERROR(VLOOKUP(K9,$A$2:$F$21,6,FALSE),0),IFERROR(VLOOKUP(L9,$A$2:$F$21,6,FALSE),0),IFERROR(VLOOKUP(M9,$A$2:$F$21,6,FALSE),0)) -> 0 | F9: =E9+D9 -> 3 | G9: =H9-D9 -> 0 | H9: =IF(O9=1E+99,$N$2,O9) -> 3 | I9: =G9-E9 -> 0 | J9: =IF(I9=0,"Sim","Não") -> Sim | K9: 4 | L9: 6 | O9: =MIN(IF($K$2:$K$21=A9,$E$2:$E$21,1E+99),IF($L$2:$L$21=A9,$E$2:$E$21,1E+99),IF($M$2:$M$21=A9,$E$2:$E$21,1E+99)) -> 1e+99
A10: 9 | B10: 3A. UX - Experiência do Usuário | C10: 7 | D10: 3 | E10: =MAX(IFERROR(VLOOKUP(K10,$A$2:$F$21,6,FALSE),0),IFERROR(VLOOKUP(L10,$A$2:$F$21,6,FALSE),0),IFERROR(VLOOKUP(M10,$A$2:$F$21,6,FALSE),0)) -> 0 | F10: =E10+D10 -> 3 | G10: =H10-D10 -> 0 | H10: =IF(O10=1E+99,$N$2,O10) -> 3 | I10: =G10-E10 -> 0 | J10: =IF(I10=0,"Sim","Não") -> Sim | K10: 7 | O10: =MIN(IF($K$2:$K$21=A10,$E$2:$E$21,1E+99),IF($L$2:$L$21=A10,$E$2:$E$21,1E+99),IF($M$2:$M$21=A10,$E$2:$E$21,1E+99)) -> 1e+99
A11: 10 | B11: 3B. Definição de Personas | C11: 9 | D11: 1 | E11: =MAX(IFERROR(VLOOKUP(K11,$A$2:$F$21,6,FALSE),0),IFERROR(VLOOKUP(L11,$A$2:$F$21,6,FALSE),0),IFERROR(VLOOKUP(M11,$A$2:$F$21,6,FALSE),0)) -> 0 | F11: =E11+D11 -> 1 | G11: =H11-D11 -> 2 | H11: =IF(O11=1E+99,$N$2,O11) -> 3 | I11: =G11-E11 -> 2 | J11: =IF(I11=0,"Sim","Não") -> Não | K11: 9 | O11: =MIN(IF($K$2:$K$21=A11,$E$2:$E$21,1E+99),IF($L$2:$L$21=A11,$E$2:$E$21,1E+99),IF($M$2:$M$21=A11,$E$2:$E$21,1E+99)) -> 1e+99
A12: 11 | B12: 3C. Jornada do Usuário | C12: 9 | D12: 2 | E12: =MAX(IFERROR(VLOOKUP(K12,$A$2:$F$21,6,FALSE),0),IFERROR(VLOOKUP(L12,$A$2:$F$21,6,FALSE),0),IFERROR(VLOOKUP(M12,$A$2:$F$21,6,FALSE),0)) -> 0 | F12: =E12+D12 -> 2 | G12: =H12-D12 -> 1 | H12: =IF(O12=1E+99,$N$2,O12) -> 3 | I12: =G12-E12 -> 1 | J12: =IF(I12=0,"Sim","Não") -> Não | K12: 9 | O12: =MIN(IF($K$2:$K$21=A12,$E$2:$E$21,1E+99),IF($L$2:$L$21=A12,$E$2:$E$21,1E+99),IF($M$2:$M$21=A12,$E$2:$E$21,1E+99)) -> 1e+99
A13: 12 | B13: 3D. UI - Interface do Usuário | C13: 9 | D13: 3 | E13: =MAX(IFERROR(VLOOKUP(K13,$A$2:$F$21,6,FALSE),0),IFERROR(VLOOKUP(L13,$A$2:$F$21,6,FALSE),0),IFERROR(VLOOKUP(M13,$A$2:$F$21,6,FALSE),0)) -> 0 | F13: =E13+D13 -> 3 | G13: =H13-D13 -> 0 | H13: =IF(O13=1E+99,$N$2,O13) -> 3 | I13: =G13-E13 -> 0 | J13: =IF(I13=0,"Sim","Não") -> Sim | K13: 9 | O13: =MIN(IF($K$2:$K$21=A13,$E$2:$E$21,1E+99),IF($L$2:$L$21=A13,$E$2:$E$21,1E+99),IF($M$2:$M$21=A13,$E$2:$E$21,1E+99)) -> 1e+99
A14: 13 | B14: 4A. Preparação do Ambiente | C14: 5 | D14: 2 | E14: =MAX(IFERROR(VLOOKUP(K14,$A$2:$F$21,6,FALSE),0),IFERROR(VLOOKUP(L14,$A$2:$F$21,6,FALSE),0),IFERROR(VLOOKUP(M14,$A$2:$F$21,6,FALSE),0)) -> 0 | F14: =E14+D14 -> 2 | G14: =H14-D14 -> 1 | H14: =IF(O14=1E+99,$N$2,O14) -> 3 | I14: =G14-E14 -> 1 | J14: =IF(I14=0,"Sim","Não") -> Não | K14: 5 | O14: =MIN(IF($K$2:$K$21=A14,$E$2:$E$21,1E+99),IF($L$2:$L$21=A14,$E$2:$E$21,1E+99),IF($M$2:$M$21=A14,$E$2:$E$21,1E+99)) -> 1e+99
A15: 14 | B15: 4B. Configuração do repositório | C15: 13 | D15: 1 | E15: =MAX(IFERROR(VLOOKUP(K15,$A$2:$F$21,6,FALSE),0),IFERROR(VLOOKUP(L15,$A$2:$F$21,6,FALSE),0),IFERROR(VLOOKUP(M15,$A$2:$F$21,6,FALSE),0)) -> 0 | F15: =E15+D15 -> 1 | G15: =H15-D15 -> 2 | H15: =IF(O15=1E+99,$N$2,O15) -> 3 | I15: =G15-E15 -> 2 | J15: =IF(I15=0,"Sim","Não") -> Não | K15: 13 | O15: =MIN(IF($K$2:$K$21=A15,$E$2:$E$21,1E+99),IF($L$2:$L$21=A15,$E$2:$E$21,1E+99),IF($M$2:$M$21=A15,$E$2:$E$21,1E+99)) -> 1e+99
A16: 15 | B16: 4C. Configuração do Banco de Dados e Nuvem | C16: 14 | D16: 3 | E16: =MAX(IFERROR(VLOOKUP(K16,$A$2:$F$21,6,FALSE),0),IFERROR(VLOOKUP(L16,$A$2:$F$21,6,FALSE),0),IFERROR(VLOOKUP(M16,$A$2:$F$21,6,FALSE),0)) -> 0 | F16: =E16+D16 -> 3 | G16: =H16-D16 -> 0 | H16: =IF(O16=1E+99,$N$2,O16) -> 3 | I16: =G16-E16 -> 0 | J16: =IF(I16=0,"Sim","Não") -> Sim | K16: 14 | O16: =MIN(IF($K$2:$K$21=A16,$E$2:$E$21,1E+99),IF($L$2:$L$21=A16,$E$2:$E$21,1E+99),IF($M$2:$M$21=A16,$E$2:$E$21,1E+99)) -> 1e+99
A17: 16 | B17: 4D. Backend | C17: 15 | D17: 3 | E17: =MAX(IFERROR(VLOOKUP(K17,$A$2:$F$21,6,FALSE),0),IFERROR(VLOOKUP(L17,$A$2:$F$21,6,FALSE),0),IFERROR(VLOOKUP(M17,$A$2:$F$21,6,FALSE),0)) -> 0 | F17: =E17+D17 -> 3 | G17: =H17-D17 -> 0 | H17: =IF(O17=1E+99,$N$2,O17) -> 3 | I17: =G17-E17 -> 0 | J17: =IF(I17=0,"Sim","Não") -> Sim | K17: 15 | O17: =MIN(IF($K$2:$K$21=A17,$E$2:$E$21,1E+99),IF($L$2:$L$21=A17,$E$2:$E$21,1E+99),IF($M$2:$M$21=A17,$E$2:$E$21,1E+99)) -> 1e+99
A18: 17 | B18: 4E. Implementação do ETL | C18: 16 | D18: 2 | E18: =MAX(IFERROR(VLOOKUP(K18,$A$2:$F$21,6,FALSE),0),IFERROR(VLOOKUP(L18,$A$2:$F$21,6,FALSE),0),IFERROR(VLOOKUP(M18,$A$2:$F$21,6,FALSE),0)) -> 0 | F18: =E18+D18 -> 2 | G18: =H18-D18 -> 1 | H18: =IF(O18=1E+99,$N$2,O18) -> 3 | I18: =G18-E18 -> 1 | J18: =IF(I18=0,"Sim","Não") -> Não | K18: 16 | O18: =MIN(IF($K$2:$K$21=A18,$E$2:$E$21,1E+99),IF($L$2:$L$21=A18,$E$2:$E$21,1E+99),IF($M$2:$M$21=A18,$E$2:$E$21,1E+99)) -> 1e+99
A19: 18 | B19: 4F. Criação de APIs de Integração | C19: 16 | D19: 3 | E19: =MAX(IFERROR(VLOOKUP(K19,$A$2:$F$21,6,FALSE),0),IFERROR(VLOOKUP(L19,$A$2:$F$21,6,FALSE),0),IFERROR(VLOOKUP(M19,$A$2:$F$21,6,FALSE),0)) -> 0 | F19: =E19+D19 -> 3 | G19: =H19-D19 -> 0 | H19: =IF(O19=1E+99,$N$2,O19) -> 3 | I19: =G19-E19 -> 0 | J19: =IF(I19=0,"Sim","Não") -> Sim | K19: 16 | O19: =MIN(IF($K$2:$K$21=A19,$E$2:$E$21,1E+99),IF($L$2:$L$21=A19,$E$2:$E$21,1E+99),IF($M$2:$M$21=A19,$E$2:$E$21,1E+99)) -> 1e+99
A20: 19 | B20: 4G. Autenticação e perfis de acesso | C20: 16 | D20: 2 | E20: =MAX(IFERROR(VLOOKUP(K20,$A$2:$F$21,6,FALSE),0),IFERROR(VLOOKUP(L20,$A$2:$F$21,6,FALSE),0),IFERROR(VLOOKUP(M20,$A$2:$F$21,6,FALSE),0)) -> 0 | F20: =E20+D20 -> 2 | G20: =H20-D20 -> 1 | H20: =IF(O20=1E+99,$N$2,O20) -> 3 | I20: =G20-E20 -> 1 | J20: =IF(I20=0,"Sim","Não") -> Não | K20: 16 | O20: =MIN(IF($K$2:$K$21=A20,$E$2:$E$21,1E+99),IF($L$2:$L$21=A20,$E$2:$E$21,1E+99),IF($M$2:$M$21=A20,$E$2:$E$21,1E+99)) -> 1e+99
A21: 20 | B21: 4H. Inteligência Artificial / Machine Learning | C21: 17 | D21: 3 | E21: =MAX(IFERROR(VLOOKUP(K21,$A$2:$F$21,6,FALSE),0),IFERROR(VLOOKUP(L21,$A$2:$F$21,6,FALSE),0),IFERROR(VLOOKUP(M21,$A$2:$F$21,6,FALSE),0)) -> 0 | F21: =E21+D21 -> 3 | G21: =H21-D21 -> 0 | H21: =IF(O21=1E+99,$N$2,O21) -> 3 | I21: =G21-E21 -> 0 | J21: =IF(I21=0,"Sim","Não") -> Sim | K21: 17 | O21: =MIN(IF($K$2:$K$21=A21,$E$2:$E$21,1E+99),IF($L$2:$L$21=A21,$E$2:$E$21,1E+99),IF($M$2:$M$21=A21,$E$2:$E$21,1E+99)) -> 1e+99

Sheet Gestão de Custo
B2: Previsões de Orçamento | J2: InovaTech
C4: 1 | D4: Capa | F4: Instruções, Histórico de Alterações e as Aprovações
C5: =C4+1 -> 2 | D5: Orçado | F5: Detalhamento dos investimentos orçados
C6: =C5+1 -> 3 | D6: Realizado | F6: Detalhamento dos investimentos realizados
C7: =C6+1 -> 4 | D7: Status | F7: Status comparando Orçado x Realizado
C8: =C7+1 -> 5 | D8: Parâmetros | F8: Parâmetros usados nas outras abas da planilha.
D10: Fonte | E10: https://escritoriodeprojetos.com.br/download/previsoes-do-orcamento/
B14: Controle de Versões
B15: Versão | C15: Data | D15: Autor | E15: Notas da Revisão
B16: 1 | C16: 45958 | D16: Bruna Lira
B17: 2 | C17: 45964 | D17: Bruna Lira
B20: Instruções | D20: =TODAY() -> 45971
B21: Ref. | C21: Aba | D21: Respons | E21: Passos
B22: 0 | C22: Param | D22: PMO | E22: Inserir o Custo de Capital e o Retorno Requerido do Investimento (ROI). Preencher também o nome do projeto (InovaTech) e o patrocinador (Cannoli).
B23: 1 | C23: Orçado | D23: Gerente de Projetos | E23: Preencher as informações de identificação: nome do projeto, solicitante e patrocinador.
B24: =B23+1 -> 2 | C24: Orçado | D24: Gerente de Projetos | E24: Inserir na coluna B o nome de cada gasto ou categoria de despesa (Infraestrutura, Desenvolvimento, Licenças, Marketing, etc.). Caso haja mais de 5 categorias, agrupar ou ajustar conforme necessário.
B25: =B24+1 -> 3 | C25: Orçado | D25: Gerente de Projetos | E25: Sempre que possível, descrever como foi calculado o valor de cada gasto (ex.: cotação, pesquisa de mercado, valor médio).
B26: =B25+1 -> 4 | C26: Orçado | D26: Gerente de Projetos | E26: Validar se todos os custos estão lançados corretamente e revisar fórmulas de soma e totalização.
B27: =B26+1 -> 5 | C27: Orçado | D27: Gerente de Projetos | E27: Preencher na coluna B o nome dos custos adicionais ou operacionais, se aplicável.
B28: =B27+1 -> 6 | C28: Orçado | D28: Gerente de Projetos | E28: Verificar se os valores orçados estão coerentes com o orçamento total disponível e atualizar caso haja revisões.
B29: =B28+1 -> 7 | C29: Orçado | D29: Gerente de Projetos | E29: Registrar os valores efetivamente realizados mês a mês. Caso não haja detalhamento, inserir o valor total do mês na linha de consolidação.
B30: =B29+1 -> 8 | C30: Realizado | D30: Gerente de Projetos | E30: Acompanhar o comparativo entre Orçado x Realizado e verificar os percentuais de desvio (%). Gráfico e cálculos são automáticos, não editar fórmulas.
B31: =B30+1 -> 9 | C31: Todos | D31: Equipe Toda | E31: Garantir que todas as abas estejam atualizadas antes das reuniões de acompanhamento mensal do projeto.
B32: =B31+1 -> 10
B33: =B32+1 -> 11
B34: =B33+1 -> 12
B36: Aprovações
B37: Ref. | C37: Data | D37: Participante | E37: Assinatura
B38: 1 | C38: 45968 | D38: Rafaela Coelho | E38: R.C
B39: 2
B40: 3

Sheet Orcado
B2: Identificação do Projeto | D2: Mês
B3: Nome do Projeto | C3: InovaTech | E3: 45870 | F3: 45909 | G3: =DATE(YEAR(F3),MONTH(F3)+1,DAY(F3)) -> 45939 | H3: =DATE(YEAR(G3),MONTH(G3)+1,DAY(G3)) -> 45970 | I3: =DATE(YEAR(H3),MONTH(H3)+1,DAY(H3)) -> 46000 | J3: =DATE(YEAR(I3),MONTH(I3)+1,DAY(I3)) -> 46031 | K3: =DATE(YEAR(J3),MONTH(J3)+1,DAY(J3)) -> 46062 | L3: =DATE(YEAR(K3),MONTH(K3)+1,DAY(K3)) -> 46090 | M3: =DATE(YEAR(L3),MONTH(L3)+1,DAY(L3)) -> 46121 | N3: =DATE(YEAR(M3),MONTH(M3)+1,DAY(M3)) -> 46151 | ... P3: =DATE(YEAR(O3),MONTH(O3)+1,DAY(O3)) -> 46212 | Q3: TOTAL
B4: Patrocinador | C4: Cannoli – Parceira Comercial | D4: 0 | E4: 1 | F4: =E4+1 -> 2 | G4: =F4+1 -> 3 | H4: =G4+1 -> 4 | I4: =H4+1 -> 5 | J4: =I4+1 -> 6 | K4: =J4+1 -> 7 | L4: =K4+1 -> 8 | M4: =L4+1 -> 9 | ... P4: =O4+1 -> 12
B5: Investimento inicial Total | C5: 184000 | D5: =SUM(D9+D11+D13+D15+D17+D19+D21+D23+D25+D27+D29) -> 183200 | E5: =SUM(E33:E46)+E9+E11+E13+E15+E17+E19+E21+E23+E25+E27+E29 -> 10888.23 | F5: =SUM(F33:F46)+F9+F11+F13+F15+F17+F19+F21+F23+F25+F27 -> 10805.458 | G5: =SUM(G33:G46)+G9+G11+G13+G15+G17+G19+G21+G23+G25+G27 -> 7986.0038 | H5: =SUM(H33:H46)+H9+H11+H13+H15+H17+H19+H21+H23+H25+H27 -> 8234.6042 | I5: =SUM(I33:I46)+I9+I11+I13+I15+I17+I19+I21+I23+I25+I27 -> 9058.0646 | J5: =SUM(J33:J46)+J9+J11+J13+J15+J17+J19+J21+J23+J25+J27 -> 9963.8711 | K5: =SUM(K33:K46)+K9+K11+K13+K15+K17+K19+K21+K23+K25+K27 -> 10960.258 | L5: =SUM(L33:L46)+L9+L11+L13+L15+L17+L19+L21+L23+L25+L27 -> 12056.284 | M5: =SUM(M33:M46)+M9+M11+M13+M15+M17+M19+M21+M23+M25+M27 -> 13261.912 | ... P5: =SUM(P33:P46)+P9+P11+P13+P15+P17+P19+P21+P23+P25+P27 -> 17651.605 | Q5: =SUM(D5:P5) -> 324701.31
B6: Investimento Acumulado | C6: 0 | D6: =D5 -> 183200 | E6: =D6+E5 -> 194088.23 | F6: =E6+F5 -> 204893.69 | G6: =F6+G5 -> 212879.69 | H6: =G6+H5 -> 221114.3 | I6: =H6+I5 -> 230172.36 | J6: =I6+J5 -> 240136.23 | K6: =J6+K5 -> 251096.49 | L6: =K6+L5 -> 263152.77 | ... P6: =O6+P5 -> 324701.31
B7: Orçado | C7: Explicação
B8: Investimento c/ taxa de crescimento | C8: Para facilitar o cálculo dos gastos do projeto InovaTech, foi aplicada uma taxa média de crescimento mensal de 10% sobre cada etapa de desenvolvimento.
B9: Planejamento e Definição do Escopo | C9: Reuniões com stakeholders da Cannoli, levantamento de requisitos e cronograma. | D9: 8000 | E9: 4000 | F9: =E9*(1+F8) -> 4000 | G9: 500 | H9: 0 | I9: =H9*(1+I8) -> 0 | J9: =I9*(1+J8) -> 0 | K9: =J9*(1+K8) -> 0 | L9: =K9*(1+L8) -> 0 | M9: =L9*(1+M8) -> 0 | N9: =M9*(1+N8) -> 0 | O9: =N9*(1+O8) -> 0 | P9: =O9*(1+P8) -> 0 | Q9: =SUM(E9:P9) -> 8500
B10: Taxa de Crescimento de 10% | C10: Taxa de crescimento de investimento de 10% ao mês MOM | F10: 0.1 | G10: =F10 -> 0.1 | H10: =G10 -> 0.1 | I10: =H10 -> 0.1 | J10: =I10 -> 0.1 | K10: =J10 -> 0.1 | L10: =K10 -> 0.1 | M10: =L10 -> 0.1 | N10: =M10 -> 0.1 | ... P10: =O10 -> 0.1
B11: Análise de Dados e Modelagem | C11: Estruturação do banco de dados, estudo das métricas e indicadores que serão exibidos. | D11: 21000 | E11: 794.96 | F11: =E11*(1+F10) -> 874.456 | G11: =F11*(1+G10) -> 961.9016 | H11: =G11*(1+H10) -> 1058.0918 | I11: =H11*(1+I10) -> 1163.9009 | J11: =I11*(1+J10) -> 1280.291 | K11: =J11*(1+K10) -> 1408.3201 | L11: =K11*(1+L10) -> 1549.1521 | M11: =L11*(1+M10) -> 1704.0674 | ... P11: =O11*(1+P10) -> 2268.1137 | Q11: =SUM(E11:P11) -> 16999.65
B12: Taxa de Crescimento de 10% | C12: Taxa de crescimento de investimento de 10% ao mês MOM | F12: 0.1 | G12: =F12 -> 0.1 | H12: =G12 -> 0.1 | I12: =H12 -> 0.1 | J12: =I12 -> 0.1 | K12: =J12 -> 0.1 | L12: =K12 -> 0.1 | M12: =L12 -> 0.1 | N12: =M12 -> 0.1 | ... P12: =O12 -> 0.1
B13: Design de Interface (UI/UX) | C13: Criação dos dashboards no Figma, escolha da paleta e layout. | D13: 13200 | E13: 617.29 | F13: =E13*(1+F12) -> 679.019 | G13: =F13*(1+G12) -> 746.9209 | H13: =G13*(1+H12) -> 821.61299 | I13: =H13*(1+I12) -> 903.77429 | J13: =I13*(1+J12) -> 994.15172 | K13: =J13*(1+K12) -> 1093.5669 | L13: =K13*(1+L12) -> 1202.9236 | M13: =L13*(1+M12) -> 1323.2159 | ... P13: =O13*(1+P12) -> 1761.2004 | Q13: =SUM(E13:P13) -> 13200.305
B14: Taxa de Crescimento de 10% | C14: Taxa de crescimento de investimento de 10% ao mês MOM | F14: 0.1 | G14: =F14 -> 0.1 | H14: =G14 -> 0.1 | I14: =H14 -> 0.1 | J14: =I14 -> 0.1 | K14: =J14 -> 0.1 | L14: =K14 -> 0.1 | M14: =L14 -> 0.1 | N14: =M14 -> 0.1 | ... P14: =O14 -> 0.1
B15: Desenvolvimento Backend e Frontend | C15: Construção da API Flask, integração com SQLite e desenvolvimento do painel web. | D15: 50000 | E15: 1496.43 | F15: =E15*(1+F14) -> 1646.073 | G15: =F15*(1+G14) -> 1810.6803 | H15: =G15*(1+H14) -> 1991.7483 | I15: =H15*(1+I14) -> 2190.9232 | J15: =I15*(1+J14) -> 2410.0155 | K15: =J15*(1+K14) -> 2651.017 | L15: =K15*(1+L14) -> 2916.1187 | M15: =L15*(1+M14) -> 3207.7306 | ... P15: =O15*(1+P14) -> 4269.4894 | Q15: =SUM(E15:P15) -> 32000.084
B16: Taxa de Crescimento de 10% | C16: Taxa de crescimento de investimento de 10% ao mês MOM | F16: 0.1 | G16: =F16 -> 0.1 | H16: =G16 -> 0.1 | I16: =H16 -> 0.1 | J16: =I16 -> 0.1 | K16: =J16 -> 0.1 | L16: =K16 -> 0.1 | M16: =L16 -> 0.1 | N16: =M16 -> 0.1 | ... P16: =O16 -> 0.1
B17: Integração de Dados da Cannoli | C17: Conexão com os dados reais da Cannoli, validação e testes de importação. | D17: 5000 | E17: 233.8 | F17: =E17*(1+F16) -> 257.18 | G17: =F17*(1+G16) -> 282.898 | H17: =G17*(1+H16) -> 311.1878 | I17: =H17*(1+I16) -> 342.30658 | J17: =I17*(1+J16) -> 376.53724 | K17: =J17*(1+K16) -> 414.19096 | L17: =K17*(1+L16) -> 455.61006 | M17: =L17*(1+M16) -> 501.17106 | ... P17: =O17*(1+P16) -> 667.05869 | Q17: =SUM(E17:P17) -> 4999.6455
B18: Taxa de Crescimento de 10% | C18: Taxa de crescimento de investimento de 10% ao mês MOM | F18: 0.1 | G18: =F18 -> 0.1 | H18: =G18 -> 0.1 | I18: =H18 -> 0.1 | J18: =I18 -> 0.1 | K18: =J18 -> 0.1 | L18: =K18 -> 0.1 | M18: =L18 -> 0.1 | N18: =M18 -> 0.1 | ... P18: =O18 -> 0.1
B19: Testes e Validação de Funcionalidades | C19: Teste de login, gráficos, relatórios e responsividade. | D19: 12000 | E19: 542.45 | F19: =E19*(1+F18) -> 596.695 | G19: =F19*(1+G18) -> 656.3645 | H19: =G19*(1+H18) -> 722.00095 | I19: =H19*(1+I18) -> 794.20105 | J19: =I19*(1+J18) -> 873.62115 | K19: =J19*(1+K18) -> 960.98326 | L19: =K19*(1+L18) -> 1057.0816 | M19: =L19*(1+M18) -> 1162.7897 | ... P19: =O19*(1+P18) -> 1547.6732 | Q19: =SUM(E19:P19) -> 11599.905
B20: Taxa de Crescimento de 10% | C20: Taxa de crescimento de investimento de 10% ao mês MOM | F20: 0.1 | G20: =F20 -> 0.1 | H20: =G20 -> 0.1 | I20: =H20 -> 0.1 | J20: =I20 -> 0.1 | K20: =J20 -> 0.1 | L20: =K20 -> 0.1 | M20: =L20 -> 0.1 | N20: =M20 -> 0.1 | ... P20: =O20 -> 0.1
B21: Apresentação para a Cannoli | C21: Entrega da primeira versão funcional e coleta de feedback. | D21: 15000 | E21: 869.8 | F21: =E21*(1+F20) -> 956.78 | G21: =F21*(1+G20) -> 1052.458 | H21: =G21*(1+H20) -> 1157.7038 | I21: =H21*(1+I20) -> 1273.4742 | J21: =I21*(1+J20) -> 1400.8216 | K21: =J21*(1+K20) -> 1540.9038 | L21: =K21*(1+L20) -> 1694.9941 | M21: =L21*(1+M20) -> 1864.4935 | ... P21: =O21*(1+P20) -> 2481.6409 | Q21: =SUM(E21:P21) -> 18600.05
B22: Taxa de Crescimento de 10% | C22: Taxa de crescimento de investimento de 10% ao mês MOM | F22: 0.1 | G22: =F22 -> 0.1 | H22: =G22 -> 0.1 | I22: =H22 -> 0.1 | J22: =I22 -> 0.1 | K22: =J22 -> 0.1 | L22: =K22 -> 0.1 | M22: =L22 -> 0.1 | N22: =M22 -> 0.1 | ... P22: =O22 -> 0.1
B23: Ajustes Pós-Feedback | C23: Correções e melhorias de interface e performance. | D23: 16000 | E23: 514.4 | F23: =E23*(1+F22) -> 565.84 | G23: =F23*(1+G22) -> 622.424 | H23: =G23*(1+H22) -> 684.6664 | I23: =H23*(1+I22) -> 753.13304 | J23: =I23*(1+J22) -> 828.44634 | K23: =J23*(1+K22) -> 911.29098 | L23: =K23*(1+L22) -> 1002.4201 | M23: =L23*(1+M22) -> 1102.6621 | ... P23: =O23*(1+P22) -> 1467.6432 | Q23: =SUM(E23:P23) -> 11000.076
B24: Taxa de Crescimento de 10% | C24: Taxa de crescimento de investimento de 10% ao mês MOM | F24: 0.1 | G24: =F24 -> 0.1 | H24: =G24 -> 0.1 | I24: =H24 -> 0.1 | J24: =I24 -> 0.1 | K24: =J24 -> 0.1 | L24: =K24 -> 0.1 | M24: =L24 -> 0.1 | N24: =M24 -> 0.1 | ... P24: =O24 -> 0.1
B25: Relatório e Demonstração Final | C25: Preparação do pitch, apresentações e entrega para banca/professor. | D25: 14000 | E25: 701.45 | F25: =E25*(1+F24) -> 771.595 | G25: =F25*(1+G24) -> 848.7545 | H25: =G25*(1+H24) -> 933.62995 | I25: =H25*(1+I24) -> 1026.9929 | J25: =I25*(1+J24) -> 1129.6922 | K25: =J25*(1+K24) -> 1242.6615 | L25: =K25*(1+L24) -> 1366.9276 | M25: =L25*(1+M24) -> 1503.6204 | ... P25: =O25*(1+P24) -> 2001.3187 | Q25: =SUM(E25:P25) -> 15000.006
B26: Taxa de Crescimento de 10% | C26: Taxa de crescimento de investimento de 10% ao mês MOM | F26: 0.1 | G26: =F26 -> 0.1 | H26: =G26 -> 0.1 | I26: =H26 -> 0.1 | J26: =I26 -> 0.1 | K26: =J26 -> 0.1 | L26: =K26 -> 0.1 | M26: =L26 -> 0.1 | N26: =M26 -> 0.1 | ... P26: =O26 -> 0.1
B27: Encerramento do Projeto | C27: Documentação final e análise dos indicadores do projeto. | D27: 9000 | E27: 416.2 | F27: =E27*(1+F26) -> 457.82 | G27: =F27*(1+G26) -> 503.602 | H27: =G27*(1+H26) -> 553.9622 | I27: =H27*(1+I26) -> 609.35842 | J27: =I27*(1+J26) -> 670.29426 | K27: =J27*(1+K26) -> 737.32369 | L27: =K27*(1+L26) -> 811.05606 | M27: =L27*(1+M26) -> 892.16166 | ... P27: =O27*(1+P26) -> 1187.4672 | Q27: =SUM(E27:P27) -> 8900.1389
B28: Taxa de Crescimento de 10% | C28: Taxa de crescimento de investimento de 10% ao mês MOM | F28: 0.1 | G28: =F28 -> 0.1 | H28: =G28 -> 0.1 | I28: =H28 -> 0.1 | J28: =I28 -> 0.1 | K28: =J28 -> 0.1 | L28: =K28 -> 0.1 | M28: =L28 -> 0.1 | N28: =M28 -> 0.1 | ... P28: =O28 -> 0.1
B29: Expansão | C29: Feedback e adapção | D29: 20000 | E29: 701.45 | F29: =E29*(1+F28) -> 771.595 | G29: =F29*(1+G28) -> 848.7545 | H29: =G29*(1+H28) -> 933.62995 | I29: =H29*(1+I28) -> 1026.9929 | J29: =I29*(1+J28) -> 1129.6922 | K29: =J29*(1+K28) -> 1242.6615 | L29: =K29*(1+L28) -> 1366.9276 | M29: =L29*(1+M28) -> 1503.6204 | ... P29: =O29*(1+P28) -> 2001.3187 | Q29: =SUM(E29:P29) -> 15000.006
B32: Investimentos
B33: Custo de Implementação | D33: 183200 | E33: 0 | F33: =E33 -> 0 | G33: =F33 -> 0 | H33: =G33 -> 0 | I33: =H33 -> 0 | J33: =I33 -> 0 | K33: =J33 -> 0 | L33: =K33 -> 0 | M33: =L33 -> 0 | ... P33: =O33 -> 0 | Q33: =SUM(D33:P33) -> 183200
B34: Custo da Operação | F34: =E34 -> 0 | G34: =F34 -> 0 | H34: =G34 -> 0 | I34: =H34 -> 0 | J34: =I34 -> 0 | K34: =J34 -> 0 | L34: =K34 -> 0 | M34: =L34 -> 0 | ... P34: =O34 -> 0 | Q34: =SUM(D34:P34) -> 0
B35: Custos de Treinamento | F35: =E35 -> 0 | G35: =F35 -> 0 | H35: =G35 -> 0 | I35: =H35 -> 0 | J35: =I35 -> 0 | K35: =J35 -> 0 | L35: =K35 -> 0 | M35: =L35 -> 0 | ... P35: =O35 -> 0 | Q35: =SUM(D35:P35) -> 0
B51: Indicadores Financeiros
B53: NPV/VPL | D53: =NPV(Param!D4,E5:P5)+D5 -> 324701.31
B54: Payback | D54: =COUNTIF(D6:P6,"<=0") -> 0
B55: ROI | D55: =SUM(E5:P5)/-D5 -> -0.77238706

Sheet Realizado
B2: =Orcado!B2 -> Identificação do Projeto | E2: Mês
B3: Nome do Projeto | C3: InovaTech – Dashboard Inteligente para a Cannoli | E3: =Orcado!E3 -> 45870 | F3: =Orcado!F3 -> 45909 | G3: =Orcado!G3 -> 45939 | H3: =Orcado!H3 -> 45970 | I3: =Orcado!I3 -> 46000 | J3: =Orcado!J3 -> 46031 | K3: 46023 | L3: =Orcado!L3 -> 46090 | M3: =Orcado!M3 -> 46121 | N3: =Orcado!N3 -> 46151 | O3: =Orcado!O3 -> 46182 | P3: =Orcado!P3 -> 46212 | Q3: TOTAL
B4: Patrocinador | C4: Cannoli – Rede de Restaurantes | D4: 0 | E4: 1 | F4: =E4+1 -> 2 | G4: =F4+1 -> 3 | H4: =G4+1 -> 4 | I4: =H4+1 -> 5 | J4: =I4+1 -> 6 | K4: =J4+1 -> 7 | L4: =K4+1 -> 8 | M4: =L4+1 -> 9 | ... P4: =O4+1 -> 12
B5: Investimento Total | D5: =SUM(D9+D11+D13+D15+D17+D19+D21+D23+D25+D27+D29) -> 168500 | E5: =SUM(E39:E52)+E9+E11+E13+E15+E17+E19+E21+E23+E25+E27+E29 -> 7987.4 | F5: =SUM(F9+F11+F13+F15+F17+F19+F21+F23+F25+F27+F29) -> 8708.14 | G5: =SUM(G9+G11+G13+G15+G17+G19+G21+G23+G25+G27+G29) -> 9500.954 | H5: =SUM(H9+H11+H13+H15+H17+H19+H21+H23+H25+H27+H29) -> 10373.049 | I5: =SUM(I9+I11+I13+I15+I17+I19+I21+I23+I25+I27+I29) -> 11332.354 | J5: =SUM(J9+J11+J13+J15+J17+J19+J21+J23+J25+J27+J29) -> 12387.59 | K5: =SUM(K9+K11+K13+K15+K17+K19+K21+K23+K25+K27+K29) -> 13548.349 | L5: =SUM(L9+L11+L13+L15+L17+L19+L21+L23+L25+L27+L29) -> 14825.184 | M5: =SUM(M9+M11+M13+M15+M17+M19+M21+M23+M25+M27+M29) -> 16229.702 | ... P5: =SUM(P9+P11+P13+P15+P17+P19+P21+P23+P25+P27+P29) -> 21343.553 | Q5: =SUM(E5:P5) -> 163485.09
B6: Investimento Acumulado | D6: =D5 -> 168500 | E6: =D6+E5 -> 176487.4 | F6: =E6+F5 -> 185195.54 | G6: =F6+G5 -> 194696.49 | H6: =G6+H5 -> 205069.54 | I6: =H6+I5 -> 216401.9 | J6: =I6+J5 -> 228789.49 | K6: =J6+K5 -> 242337.84 | L6: =K6+L5 -> 257163.02 | ... P6: =O6+P5 -> 331985.09
B7: Realizado | C7: Explicação
B8: Investimento c/ taxa de crescimento
B9: =Orcado!B9 -> Planejamento e Definição do Escopo | C9: Reuniões concluídas com stakeholders da Cannoli, levantamento de requisitos finalizado e escopo aprovado. | D9: 8500 | E9: 780 | F9: =E9*(1+F8) -> 780 | G9: =F9*(1+G8) -> 780 | H9: =G9*(1+H8) -> 780 | I9: =H9*(1+I8) -> 780 | J9: =I9*(1+J8) -> 780 | K9: =J9*(1+K8) -> 780 | L9: =K9*(1+L8) -> 780 | M9: =L9*(1+M8) -> 780 | ... P9: =O9*(1+P8) -> 780 | Q9: =SUM(E9:P9) -> 9360
F10: 0.1 | G10: 0.1 | H10: 0.1 | I10: 0.1 | J10: 0.1 | K10: 0.1 | L10: 0.1 | M10: 0.1 | N10: 0.1 | O10: 0.1 | P10: 0.1
B11: =Orcado!B11 -> Análise de Dados e Modelagem | C11: Banco de dados estruturado, métricas definidas e primeiros testes de extração concluídos. | D11: 20300 | E11: 780 | F11: =E11*(1+F10) -> 858 | G11: =F11*(1+G10) -> 943.8 | H11: =G11*(1+H10) -> 1038.18 | I11: =H11*(1+I10) -> 1141.998 | J11: =I11*(1+J10) -> 1256.1978 | K11: =J11*(1+K10) -> 1381.8176 | L11: =K11*(1+L10) -> 1519.9993 | M11: =L11*(1+M10) -> 1671.9993 | ... P11: =O11*(1+P10) -> 2225.431 | Q11: =SUM(E11:P11) -> 16679.741
F12: 0.1 | G12: =F12 -> 0.1 | H12: =G12 -> 0.1 | I12: =H12 -> 0.1 | J12: =I12 -> 0.1 | K12: =J12 -> 0.1 | L12: =K12 -> 0.1 | M12: =L12 -> 0.1 | N12: =M12 -> 0.1 | ... P12: =O12 -> 0.1
B13: =Orcado!B13 -> Design de Interface (UI/UX) | C13: Protótipo dos dashboards finalizado no Figma e validado pela equipe; layout aprovado. | D13: 13900 | E13: 700 | F13: =E13*(1+F12) -> 770 | G13: =F13*(1+G12) -> 847 | H13: =G13*(1+H12) -> 931.7 | I13: =H13*(1+I12) -> 1024.87 | J13: =I13*(1+J12) -> 1127.357 | K13: =J13*(1+K12) -> 1240.0927 | L13: =K13*(1+L12) -> 1364.102 | M13: =L13*(1+M12) -> 1500.5122 | ... P13: =O13*(1+P12) -> 1997.1817 | Q13: =SUM(E13:P13) -> 14968.999
F14: 0.1 | G14: =F14 -> 0.1 | H14: =G14 -> 0.1 | I14: =H14 -> 0.1 | J14: =I14 -> 0.1 | K14: =J14 -> 0.1 | L14: =K14 -> 0.1 | M14: =L14 -> 0.1 | N14: =M14 -> 0.1 | ... P14: =O14 -> 0.1
B15: =Orcado!B15 -> Desenvolvimento Backend e Frontend | C15: API Flask concluída, integração com SQLite implementada e painel web funcional. | D15: 52000 | E15: 1700 | F15: =E15*(1+F14) -> 1870 | G15: =F15*(1+G14) -> 2057 | H15: =G15*(1+H14) -> 2262.7 | I15: =H15*(1+I14) -> 2488.97 | J15: =I15*(1+J14) -> 2737.867 | K15: =J15*(1+K14) -> 3011.6537 | L15: =K15*(1+L14) -> 3312.8191 | M15: =L15*(1+M14) -> 3644.101 | ... P15: =O15*(1+P14) -> 4850.2984 | Q15: =SUM(E15:P15) -> 36353.282
F16: 0.1 | G16: =F16 -> 0.1 | H16: =G16 -> 0.1 | I16: =H16 -> 0.1 | J16: =I16 -> 0.1 | K16: =J16 -> 0.1 | L16: =K16 -> 0.1 | M16: =L16 -> 0.1 | N16: =M16 -> 0.1 | ... P16: =O16 -> 0.1
B17: =Orcado!B17 -> Integração de Dados da Cannoli | C17: Conexão com dados reais da Cannoli estabelecida, testes de importação e segurança executados. | D17: 4500 | E17: 203 | F17: =E17*(1+F16) -> 223.3 | G17: =F17*(1+G16) -> 245.63 | H17: =G17*(1+H16) -> 270.193 | I17: =H17*(1+I16) -> 297.2123 | J17: =I17*(1+J16) -> 326.93353 | K17: =J17*(1+K16) -> 359.62688 | L17: =K17*(1+L16) -> 395.58957 | M17: =L17*(1+M16) -> 435.14853 | ... P17: =O17*(1+P16) -> 579.18269 | Q17: =SUM(E17:P17) -> 4341.0096
F18: 0.1 | G18: =F18 -> 0.1 | H18: =G18 -> 0.1 | I18: =H18 -> 0.1 | J18: =I18 -> 0.1 | K18: =J18 -> 0.1 | L18: =K18 -> 0.1 | M18: =L18 -> 0.1 | N18: =M18 -> 0.1 | ... P18: =O18 -> 0.1
B19: =Orcado!B19 -> Testes e Validação de Funcionalidades | C19: Testes de login, gráficos e relatórios realizados com sucesso; bugs críticos corrigidos. | D19: 11600 | E19: 520 | F19: =E19*(1+F18) -> 572 | G19: =F19*(1+G18) -> 629.2 | H19: =G19*(1+H18) -> 692.12 | I19: =H19*(1+I18) -> 761.332 | J19: =I19*(1+J18) -> 837.4652 | K19: =J19*(1+K18) -> 921.21172 | L19: =K19*(1+L18) -> 1013.3329 | M19: =L19*(1+M18) -> 1114.6662 | ... P19: =O19*(1+P18) -> 1483.6207 | Q19: =SUM(E19:P19) -> 11119.828
F20: 0.1 | G20: =F20 -> 0.1 | H20: =G20 -> 0.1 | I20: =H20 -> 0.1 | J20: =I20 -> 0.1 | K20: =J20 -> 0.1 | L20: =K20 -> 0.1 | M20: =L20 -> 0.1 | N20: =M20 -> 0.1 | ... P20: =O20 -> 0.1
B21: =Orcado!B21 -> Apresentação para a Cannoli | C21: Primeira versão entregue e feedback documentado para ajustes e melhorias. | D21: 14500 | E21: 950 | F21: =E21*(1+F20) -> 1045 | G21: =F21*(1+G20) -> 1149.5 | H21: =G21*(1+H20) -> 1264.45 | I21: =H21*(1+I20) -> 1390.895 | J21: =I21*(1+J20) -> 1529.9845 | K21: =J21*(1+K20) -> 1682.983 | L21: =K21*(1+L20) -> 1851.2812 | M21: =L21*(1+M20) -> 2036.4094 | ... P21: =O21*(1+P20) -> 2710.4609 | Q21: =SUM(E21:P21) -> 20315.07
F22: 0.1 | G22: =F22 -> 0.1 | H22: =G22 -> 0.1 | I22: =H22 -> 0.1 | J22: =I22 -> 0.1 | K22: =J22 -> 0.1 | L22: =K22 -> 0.1 | M22: =L22 -> 0.1 | N22: =M22 -> 0.1 | ... P22: =O22 -> 0.1
B23: =Orcado!B23 -> Ajustes Pós-Feedback | C23: Melhorias aplicadas com base no retorno da Cannoli; desempenho otimizado. | D23: 16000 | E23: 514.4 | F23: =E23*(1+F22) -> 565.84 | G23: =F23*(1+G22) -> 622.424 | H23: =G23*(1+H22) -> 684.6664 | I23: =H23*(1+I22) -> 753.13304 | J23: =I23*(1+J22) -> 828.44634 | K23: =J23*(1+K22) -> 911.29098 | L23: =K23*(1+L22) -> 1002.4201 | M23: =L23*(1+M22) -> 1102.6621 | ... P23: =O23*(1+P22) -> 1467.6432 | Q23: =SUM(E23:P23) -> 11000.076
F24: 0.1 | G24: =F24 -> 0.1 | H24: =G24 -> 0.1 | I24: =H24 -> 0.1 | J24: =I24 -> 0.1 | K24: =J24 -> 0.1 | L24: =K24 -> 0.1 | M24: =L24 -> 0.1 | N24: =M24 -> 0.1 | ... P24: =O24 -> 0.1
B25: =Orcado!B25 -> Relatório e Demonstração Final | C25: Relatório de resultados e apresentação final elaborados e entregues para a banca. | D25: 11600 | E25: 720 | F25: =E25*(1+F24) -> 792 | G25: =F25*(1+G24) -> 871.2 | H25: =G25*(1+H24) -> 958.32 | I25: =H25*(1+I24) -> 1054.152 | J25: =I25*(1+J24) -> 1159.5672 | K25: =J25*(1+K24) -> 1275.5239 | L25: =K25*(1+L24) -> 1403.0763 | M25: =L25*(1+M24) -> 1543.3839 | ... P25: =O25*(1+P24) -> 2054.244 | Q25: =SUM(E25:P25) -> 15396.684
F26: 0.1 | G26: =F26 -> 0.1 | H26: =G26 -> 0.1 | I26: =H26 -> 0.1 | J26: =I26 -> 0.1 | K26: =J26 -> 0.1 | L26: =K26 -> 0.1 | M26: =L26 -> 0.1 | N26: =M26 -> 0.1 | ... P26: =O26 -> 0.1
B27: =Orcado!B27 -> Encerramento do Projeto | C27: Documentação técnica e financeira concluída; indicadores de sucesso registrados. | D27: 6000 | E27: 410 | F27: =E27*(1+F26) -> 451 | G27: =F27*(1+G26) -> 496.1 | H27: =G27*(1+H26) -> 545.71 | I27: =H27*(1+I26) -> 600.281 | J27: =I27*(1+J26) -> 660.3091 | K27: =J27*(1+K26) -> 726.34001 | L27: =K27*(1+L26) -> 798.97401 | M27: =L27*(1+M26) -> 878.87141 | ... P27: =O27*(1+P26) -> 1169.7778 | Q27: =SUM(E27:P27) -> 8767.5563
F28: 0.1 | G28: =F28 -> 0.1 | H28: =G28 -> 0.1 | I28: =H28 -> 0.1 | J28: =I28 -> 0.1 | K28: =J28 -> 0.1 | L28: =K28 -> 0.1 | M28: =L28 -> 0.1 | N28: =M28 -> 0.1 | ... P28: =O28 -> 0.1
B29: =Orcado!B29 -> Expansão | C29: Planejamento de possíveis novas integrações e versões futuras da plataforma. | D29: 9600 | E29: 710 | F29: =E29*(1+F28) -> 781 | G29: =F29*(1+G28) -> 859.1 | H29: =G29*(1+H28) -> 945.01 | I29: =H29*(1+I28) -> 1039.511 | J29: =I29*(1+J28) -> 1143.4621 | K29: =J29*(1+K28) -> 1257.8083 | L29: =K29*(1+L28) -> 1383.5891 | M29: =L29*(1+M28) -> 1521.9481 | ... P29: =O29*(1+P28) -> 2025.7129 | Q29: =SUM(E29:P29) -> 15182.841
B38: Investimentos
B39: =Orcado!B33 -> Custo de Implementação | D39: 160800 | E39: 0 | F39: =E39 -> 0 | G39: =F39 -> 0 | H39: =G39 -> 0 | I39: =H39 -> 0 | J39: =I39 -> 0 | K39: =J39 -> 0 | L39: =K39 -> 0 | M39: =L39 -> 0 | ... P39: =O39 -> 0 | Q39: =SUM(D39:P39) -> 160800
B40: =Orcado!B34 -> Custo da Operação | F40: =E40 -> 0 | G40: =F40 -> 0 | H40: =G40 -> 0 | I40: =H40 -> 0 | J40: =I40 -> 0 | K40: =J40 -> 0 | L40: =K40 -> 0 | M40: =L40 -> 0 | ... P40: =O40 -> 0 | Q40: =SUM(D40:P40) -> 0
B41: =Orcado!B35 -> Custos de Treinamento | F41: =E41 -> 0 | G41: =F41 -> 0 | H41: =G41 -> 0 | I41: =H41 -> 0 | J41: =I41 -> 0 | K41: =J41 -> 0 | L41: =K41 -> 0 | M41: =L41 -> 0 | ... P41: =O41 -> 0 | Q41: =SUM(D41:P41) -> 0
B57: Indicadores Financeiros
B59: NPV/VPL | D59: =NPV(Param!D4,E5:P5)+D5 -> 331985.09
B60: Payback | D60: =COUNTIF(D6:P6,"<=0") -> 0
B61: ROI | D61: =SUM(E5:P5)/-D5 -> -0.9702379

Sheet Gráfico -Status
B2: Períodos | C2: No Período (R$) | E2: Acumulado (R$) | G2: Desvio (R$) | H2: Desvio %
B3: Mês | C3: Orçado | D3: Realizado | E3: Orçado | F3: Realizado | G3: Diferença dos realizados
B4: 0 | C4: =HLOOKUP($B4,Orcado!$D$4:$P$5,2,FALSE) -> 183200 | D4: =HLOOKUP($B4,Realizado!$D$4:$P$5,2,FALSE) -> 168500 | E4: =C4 -> 183200 | F4: =D4 -> 168500 | G4: =F4-E4 -> -14700 | H4: =IF(E4=0,"",F4/E4-1) -> -0.080240175
B5: =B4+1 -> 1 | C5: =HLOOKUP($B5,Orcado!$D$4:$P$5,2,FALSE) -> 10888.23 | D5: =HLOOKUP($B5,Realizado!$D$4:$P$5,2,FALSE) -> 7987.4 | E5: =E4+C5 -> 194088.23 | F5: =F4+D5 -> 176487.4 | G5: =F5-E5 -> -17600.83 | H5: =F5/E5-1 -> -0.090684685
B6: =B5+1 -> 2 | C6: =HLOOKUP($B6,Orcado!$D$4:$P$5,2,FALSE) -> 10805.458 | D6: =HLOOKUP($B6,Realizado!$D$4:$P$5,2,FALSE) -> 8708.14 | E6: =E5+C6 -> 204893.69 | F6: =F5+D6 -> 185195.54 | G6: =F6-E6 -> -19698.148 | H6: =F6/E6-1 -> -0.096138384
B7: =B6+1 -> 3 | C7: =HLOOKUP($B7,Orcado!$D$4:$P$5,2,FALSE) -> 7986.0038 | D7: =HLOOKUP($B7,Realizado!$D$4:$P$5,2,FALSE) -> 9500.954 | E7: =E6+C7 -> 212879.69 | F7: =F6+D7 -> 194696.49 | G7: =F7-E7 -> -18183.198 | H7: =F7/E7-1 -> -0.085415371
B8: =B7+1 -> 4 | C8: =HLOOKUP($B8,Orcado!$D$4:$P$5,2,FALSE) -> 8234.6042 | D8: =HLOOKUP($B8,Realizado!$D$4:$P$5,2,FALSE) -> 10373.049 | E8: =E7+C8 -> 221114.3 | F8: =F7+D8 -> 205069.54 | G8: =F8-E8 -> -16044.753 | H8: =F8/E8-1 -> -0.072563162
B9: =B8+1 -> 5 | C9: =HLOOKUP($B9,Orcado!$D$4:$P$5,2,FALSE) -> 9058.0646 | D9: =HLOOKUP($B9,Realizado!$D$4:$P$5,2,FALSE) -> 11332.354 | E9: =E8+C9 -> 230172.36 | F9: =F8+D9 -> 216401.9 | G9: =F9-E9 -> -13770.463 | H9: =F9/E9-1 -> -0.059826744
B10: =B9+1 -> 6 | C10: =HLOOKUP($B10,Orcado!$D$4:$P$5,2,FALSE) -> 9963.8711 | D10: =HLOOKUP($B10,Realizado!$D$4:$P$5,2,FALSE) -> 12387.59 | E10: =E9+C10 -> 240136.23 | F10: =F9+D10 -> 228789.49 | G10: =F10-E10 -> -11346.744 | H10: =F10/E10-1 -> -0.047251279
B11: =B10+1 -> 7 | C11: =HLOOKUP($B11,Orcado!$D$4:$P$5,2,FALSE) -> 10960.258 | D11: =HLOOKUP($B11,Realizado!$D$4:$P$5,2,FALSE) -> 13548.349 | E11: =E10+C11 -> 251096.49 | F11: =F10+D11 -> 242337.84 | G11: =F11-E11 -> -8758.6535 | H11: =F11/E11-1 -> -0.034881625
B12: =B11+1 -> 8 | C12: =HLOOKUP($B12,Orcado!$D$4:$P$5,2,FALSE) -> 12056.284 | D12: =HLOOKUP($B12,Realizado!$D$4:$P$5,2,FALSE) -> 14825.184 | E12: =E11+C12 -> 263152.77 | F12: =F11+D12 -> 257163.02 | G12: =F12-E12 -> -5989.7539 | H12: =F12/E12-1 -> -0.022761508
B13: =B12+1 -> 9 | C13: =HLOOKUP($B13,Orcado!$D$4:$P$5,2,FALSE) -> 13261.912 | D13: =HLOOKUP($B13,Realizado!$D$4:$P$5,2,FALSE) -> 16229.702 | E13: =E12+C13 -> 276414.69 | F13: =F12+D13 -> 273392.72 | G13: =F13-E13 -> -3021.9643 | H13: =F13/E13-1 -> -0.01093272
B14: =B13+1 -> 10 | C14: =HLOOKUP($B14,Orcado!$D$4:$P$5,2,FALSE) -> 14588.104 | D14: =HLOOKUP($B14,Realizado!$D$4:$P$5,2,FALSE) -> 17774.672 | E14: =E13+C14 -> 291002.79 | F14: =F13+D14 -> 291167.39 | G14: =F14-E14 -> 164.6043 | H14: =F14/E14-1 -> 0.00056564508
B15: =B14+1 -> 11 | C15: =HLOOKUP($B15,Orcado!$D$4:$P$5,2,FALSE) -> 16046.914 | D15: =HLOOKUP($B15,Realizado!$D$4:$P$5,2,FALSE) -> 19474.139 | E15: =E14+C15 -> 307049.7 | F15: =F14+D15 -> 310641.53 | G15: =F15-E15 -> 3591.8297 | H15: =F15/E15-1 -> 0.011697877
B16: =B15+1 -> 12 | C16: =HLOOKUP($B16,Orcado!$D$4:$P$5,2,FALSE) -> 17651.605 | D16: =HLOOKUP($B16,Realizado!$D$4:$P$5,2,FALSE) -> 21343.553 | E16: =E15+C16 -> 324701.31 | F16: =F15+D16 -> 331985.09 | G16: =F16-E16 -> 7283.7777 | H16: =F16/E16-1 -> 0.02243224
B17: Total | C17: =SUM(C4:C16) -> 324701.31 | D17: =SUM(D4:D16) -> 331985.09
B18: Saldo Final | C18: =C17-D17 -> -7283.7777
I19: Variação de +2% indica equilíbrio e eficiência na execução orçamentária do InovaTech.
B21: Ao longo da execução do projeto InovaTech, observou-se uma variação gradual entre os valores orçados e realizados.
B22: Nos primeiros meses, o investimento real ficou abaixo do planejado devido à otimização de recursos e à adoção de ferramentas gratuitas (como Flask e SQLite).
B23: Entretanto, a partir da fase de integração e ajustes pós-feedback, houve um aumento de custos relacionado à ampliação das funcionalidades e à melhoria da experiência do usuário.
B25: No encerramento do projeto, o investimento total apresentou um desvio positivo de apenas 2%, mantendo-se dentro da margem de tolerância prevista para projetos de inovação.
B26: Esse resultado reflete uma gestão financeira eficiente, com controle de custos, boa alocação de recursos e decisões estratégicas baseadas em valor agregado.

Sheet Param
B2: Variável | C2: Tipo de Benefício | D2: Custo do Capital | E2: 184000
B3: Explicação | D3: Retorno Requerido do Investimento | E3: 0.08
